2021-05-06 15:10:03,113 pleroma_bot ERROR: Exception occurred
Traceback (most recent call last):
  File "/.local/lib/python3.9/site-packages/pleroma_bot/cli.py", line 351, in main
    with open(config_path, "r") as stream:
FileNotFoundError: [Errno 2] No such file or directory: '/config/config.yml'
